<?xml version="1.0" ?>
<sdf version="1.8">
  <model name="jawbot">
    <pose>0 0 0 0 0 0</pose> <link name="base_link">
      <pose>0 0 0.060292 0 0 0</pose>
      <inertial>
        <pose>0.00027838 0.00024581 -0.013572 0 0 0</pose>
        <mass>0.51707</mass>
        <inertia>
          <ixx>0.0010682</ixx>
          <ixy>-1.8529e-07</ixy>
          <ixz>8.343e-08</ixz>
          <iyy>0.0011009</iyy>
          <iyz>-2.7461e-07</iyz>
          <izz>0.0021554</izz>
        </inertia>
      </inertial>
      <visual name="base_link_visual">
        <geometry>
          <mesh>
            <uri>model://jawbot/meshes/base_link.STL</uri>
          </mesh>
        </geometry>
        <material>
          <ambient>1.0 1.0 1.0 1.0</ambient>
          <diffuse>1.0 1.0 1.0 1.0</diffuse>
          <specular>0.5 0.5 0.5 1.0</specular>
        </material>
      </visual>
      <collision name="base_link_collision">
        <geometry>
          <mesh>
            <uri>model://jawbot/meshes/base_link.STL</uri>
          </mesh>
        </geometry>
      </collision>
    </link>

    <link name="left_wheel_link">
      <pose>-0.00079275 0.0925 -0.00125 0 0 0</pose>
      <inertial>
        <pose>-3.7201e-08 -0.0056934 4.4552e-08 0 0 0</pose>
        <mass>0.033874</mass>
        <inertia>
          <ixx>1.2633e-05</ixx>
          <ixy>5.4997e-12</ixy>
          <ixz>2.0409e-10</ixz>
          <iyy>2.3297e-05</iyy>
          <iyz>-3.9859e-12</iyz>
          <izz>1.2634e-05</izz>
        </inertia>
      </inertial>
      <visual name="left_wheel_visual">
        <geometry>
          <mesh>
            <uri>model://jawbot/meshes/left_wheel_link.STL</uri>
          </mesh>
        </geometry>
        <material>
          <ambient>0.1 0.1 0.1 1.0</ambient>
          <diffuse>0.1 0.1 0.1 1.0</diffuse>
          <specular>0.2 0.2 0.2 1.0</specular>
        </material>
      </visual>
      <collision name="left_wheel_collision">
        <geometry>
          <mesh>
            <uri>model://jawbot/meshes/left_wheel_link.STL</uri>
          </mesh>
        </geometry>
        <surface>
          <friction>
            <ode>
              <mu>1.5</mu>
              <mu2>1.5</mu2>
            </ode>
          </friction>
        </surface>
      </collision>
    </link>

    <link name="right_wheel_link">
      <pose>-0.00079275 -0.095321 -0.00125 0 0 0</pose>
      <inertial>
        <pose>-3.0238e-09 0.0068146 -5.7962e-08 0 0 0</pose>
        <mass>0.033874</mass>
        <inertia>
          <ixx>1.2633e-05</ixx>
          <ixy>-2.0076e-12</ixy>
          <ixz>-5.7414e-10</ixz>
          <iyy>2.3297e-05</iyy>
          <iyz>-6.4887e-12</iyz>
          <izz>1.2633e-05</izz>
        </inertia>
      </inertial>
      <visual name="right_wheel_visual">
        <geometry>
          <mesh>
            <uri>model://jawbot/meshes/right_wheel_link.STL</uri>
          </mesh>
        </geometry>
        <material>
          <ambient>0.1 0.1 0.1 1.0</ambient>
          <diffuse>0.1 0.1 0.1 1.0</diffuse>
          <specular>0.2 0.2 0.2 1.0</specular>
        </material>
      </visual>
      <collision name="right_wheel_collision">
        <geometry>
          <mesh>
            <uri>model://jawbot/meshes/right_wheel_link.STL</uri>
          </mesh>
        </geometry>
        <surface>
          <friction>
            <ode>
              <mu>1.5</mu>
              <mu2>1.5</mu2>
            </ode>
          </friction>
        </surface>
      </collision>
    </link>

    <link name="caster_front_link">
      <pose>0.079207 -0.00085033 -0.00365 0 0 0</pose>
      <inertial>
        <pose>-0.0033534 0.00028383 -0.0012173 0 0 0</pose>
        <mass>0.0048487</mass>
        <inertia>
          <ixx>4.8663e-07</ixx>
          <ixy>6.9734e-13</ixy>
          <ixz>-4.0889e-08</ixz>
          <iyy>4.5501e-07</iyy>
          <iyz>-8.246e-13</iyz>
          <izz>7.829e-07</izz>
        </inertia>
      </inertial>
      <visual name="caster_front_visual">
        <geometry>
          <mesh>
            <uri>model://jawbot/meshes/caster_front_link.STL</uri>
          </mesh>
        </geometry>
        <material>
          <ambient>0.6 0.6 0.6 1.0</ambient>
          <diffuse>0.6 0.6 0.6 1.0</diffuse>
        </material>
      </visual>
      <collision name="caster_front_collision">
        <geometry>
          <mesh>
            <uri>model://jawbot/meshes/caster_front_link.STL</uri>
          </mesh>
        </geometry>
      </collision>
    </link>

    <link name="caster_front_wheel_link">
      <pose>0.065707 -0.00065033 -0.02025 0 0 0</pose>
      <inertial>
        <pose>0 -1.1102e-16 0 0 0 0</pose>
        <mass>0.010151</mass>
        <inertia>
          <ixx>7.6476e-07</ixx>
          <ixy>5.6938e-22</ixy>
          <ixz>7.0301e-42</ixz>
          <iyy>1.1586e-06</iyy>
          <iyz>6.5843e-38</iyz>
          <izz>7.6476e-07</izz>
        </inertia>
      </inertial>
      <visual name="caster_front_wheel_visual">
        <geometry>
          <mesh>
            <uri>model://jawbot/meshes/caster_front_wheel_link.STL</uri>
          </mesh>
        </geometry>
        <material>
          <ambient>0.8 0.1 0.1 1.0</ambient>
          <diffuse>0.8 0.1 0.1 1.0</diffuse>
        </material>
      </visual>
      <collision name="caster_front_wheel_collision">
        <geometry>
          <mesh>
            <uri>model://jawbot/meshes/caster_front_wheel_link.STL</uri>
          </mesh>
        </geometry>
        <surface>
          <friction>
            <ode>
              <mu>0.0</mu>
              <mu2>0.0</mu2>
            </ode>
          </friction>
        </surface>
      </collision>
    </link>

    <link name="caster_back_link">
      <pose>-0.080793 -0.00085033 -0.00365 0 0 0</pose>
      <inertial>
        <pose>-0.0033534 0.00028383 -0.0012173 0 0 0</pose>
        <mass>0.0048487</mass>
        <inertia>
          <ixx>4.8663e-07</ixx>
          <ixy>6.9734e-13</ixy>
          <ixz>-4.0889e-08</ixz>
          <iyy>4.5501e-07</iyy>
          <iyz>-8.246e-13</iyz>
          <izz>7.829e-07</izz>
        </inertia>
      </inertial>
      <visual name="caster_back_visual">
        <geometry>
          <mesh>
            <uri>model://jawbot/meshes/caster_back_link.STL</uri>
          </mesh>
        </geometry>
        <material>
          <ambient>0.6 0.6 0.6 1.0</ambient>
          <diffuse>0.6 0.6 0.6 1.0</diffuse>
        </material>
      </visual>
      <collision name="caster_back_collision">
        <geometry>
          <mesh>
            <uri>model://jawbot/meshes/caster_back_link.STL</uri>
          </mesh>
        </geometry>
      </collision>
    </link>

    <link name="caster_back_wheel_link">
      <pose>-0.094293 -0.00065033 -0.02025 0 0 0</pose>
      <inertial>
        <pose>0 -1.1102e-16 -1.1102e-16 0 0 0</pose>
        <mass>0.010151</mass>
        <inertia>
          <ixx>7.6476e-07</ixx>
          <ixy>2.9657e-21</ixy>
          <ixz>7.0301e-42</ixz>
          <iyy>1.1586e-06</iyy>
          <iyz>-7.0484e-36</iyz>
          <izz>7.6476e-07</izz>
        </inertia>
      </inertial>
      <visual name="caster_back_wheel_visual">
        <geometry>
          <mesh>
            <uri>model://jawbot/meshes/caster_back_wheel_link.STL</uri>
          </mesh>
        </geometry>
        <material>
          <ambient>0.8 0.1 0.1 1.0</ambient>
          <diffuse>0.8 0.1 0.1 1.0</diffuse>
        </material>
      </visual>
      <collision name="caster_back_wheel_collision">
        <geometry>
          <mesh>
            <uri>model://jawbot/meshes/caster_back_wheel_link.STL</uri>
          </mesh>
        </geometry>
        <surface>
          <friction>
            <ode>
              <mu>0.0</mu>
              <mu2>0.0</mu2>
            </ode>
          </friction>
        </surface>
    </collision>
    </link>

    <link name="lidar_link">
      <pose>-0.0048872 0.000614 0.162672 0 0 0</pose>
      <inertial>
        <pose>0 0 0 0 0 0</pose>
        <mass>0.01</mass>
        <inertia>
          <ixx>1e-5</ixx>
          <ixy>0</ixy>
          <ixz>0</ixz>
          <iyy>1e-5</iyy>
          <iyz>0</iyz>
          <izz>1e-5</izz>
        </inertia>
      </inertial>
      <visual name="lidar_visual">
        <geometry>
          <mesh>
            <uri>model://jawbot/meshes/lidar_link.STL</uri>
          </mesh>
        </geometry>
        <material>
          <ambient>0.0 0.0 0.0 1.0</ambient>
          <diffuse>0.0 0.0 0.0 1.0</diffuse>
        </material>
      </visual>
      <collision name="lidar_collision">
        <geometry>
          <mesh>
            <uri>model://jawbot/meshes/lidar_link.STL</uri>
          </mesh>
        </geometry>
      </collision>

      <sensor type="gpu_lidar" name="jawbot_lidar">
        <pose>0 0 0 0 0 0</pose>
        <always_on>true</always_on>
        <visualize>true</visualize>
        <update_rate>10</update_rate>
        <topic>/model/jawbot/scan</topic>
        <ray>
          <scan>
            <horizontal>
              <samples>360</samples>
              <resolution>1</resolution>
              <min_angle>-3.1415926</min_angle>
              <max_angle>3.1415926</max_angle>
            </horizontal>
          </scan>
          <range>
            <min>0.12</min>
            <max>12.0</max>
            <resolution>0.01</resolution>
          </range>
        </ray>
      </sensor>
    </link>

    <joint name="left_wheel_joint" type="revolute">
      <parent>base_link</parent>
      <child>left_wheel_link</child>
      <axis>
        <xyz>0 1 0</xyz>
        <limit>
          <lower>-1e16</lower> <upper>1e16</upper>
        </limit>
      </axis>
    </joint>

    <joint name="right_wheel_joint" type="revolute">
      <parent>base_link</parent>
      <child>right_wheel_link</child>
      <axis>
        <xyz>0 1 0</xyz>
        <limit>
          <lower>-1e16</lower>
          <upper>1e16</upper>
        </limit>
      </axis>
    </joint>

    <joint name="caster_front_joint" type="revolute">
      <parent>base_link</parent>
      <child>caster_front_link</child>
      <axis>
        <xyz>0 0 1</xyz>
        <limit>
          <lower>-1e16</lower>
          <upper>1e16</upper>
        </limit>
      </axis>
    </joint>

    <joint name="caster_front_wheel_joint" type="revolute">
      <parent>caster_front_link</parent>
      <child>caster_front_wheel_link</child>
      <axis>
        <xyz>0 1 0</xyz>
        <limit>
          <lower>-1e16</lower>
          <upper>1e16</upper>
        </limit>
      </axis>
    </joint>

    <joint name="caster_back_joint" type="revolute">
      <parent>base_link</parent>
      <child>caster_back_link</child>
      <axis>
        <xyz>0 0 1</xyz>
        <limit>
          <lower>-1e16</lower>
          <upper>1e16</upper>
        </limit>
      </axis>
    </joint>

    <joint name="caster_back_wheel_joint" type="revolute">
      <parent>caster_back_link</parent>
      <child>caster_back_wheel_link</child>
      <axis>
        <xyz>0 1 0</xyz>
        <limit>
          <lower>-1e16</lower>
          <upper>1e16</upper>
        </limit>
      </axis>
    </joint>

    <joint name="lidar_joint" type="fixed">
      <parent>base_link</parent>
      <child>lidar_link</child>
    </joint>

    <plugin filename="gz-sim-diff-drive-system" name="gz::sim::systems::DiffDrive">
      <left_joint>left_wheel_joint</left_joint>
      <right_joint>right_wheel_joint</right_joint>
      <wheel_separation>0.1878</wheel_separation>
      <wheel_radius>0.060292</wheel_radius>
      <max_linear_acceleration>2.0</max_linear_acceleration>
      <max_angular_acceleration>3.0</max_angular_acceleration>
      
      <topic>/model/jawbot/cmd_vel</topic>
      <odom_topic>/model/jawbot/odometry</odom_topic>
      <tf_topic>/model/jawbot/tf</tf_topic>
      
      <frame_id>odom</frame_id>
      <child_frame_id>base_footprint</child_frame_id>
      <odom_publish_frequency>30</odom_publish_frequency>
    </plugin>

    <plugin filename="gz-sim-joint-state-publisher-system" name="gz::sim::systems::JointStatePublisher">
      <topic>/model/jawbot/joint_states</topic>
    </plugin>

  </model>
</sdf>